2023-10-25 18:56:29,031 INFO Start polling
2023-10-25 18:56:29,357 INFO Run polling for bot @kurshkosabot id=6414216172 - 'Пресс-служба: часто задаваемые вопросы'
2023-10-25 18:56:31,112 INFO Update id=430002188 is not handled. Duration 0 ms by bot id=6414216172
2023-10-25 18:56:31,112 ERROR Cause exception while process update id=430002188 by bot id=6414216172
AttributeError: 'Bot' object has no attribute 'answer'
Traceback (most recent call last):
  File "C:\Users\alex\projects\mpit\venv\lib\site-packages\aiogram\dispatcher\dispatcher.py", line 308, in _process_update
    response = await self.feed_update(bot, update, **kwargs)
  File "C:\Users\alex\projects\mpit\venv\lib\site-packages\aiogram\dispatcher\dispatcher.py", line 157, in feed_update
    response = await self.update.wrap_outer_middleware(
  File "C:\Users\alex\projects\mpit\venv\lib\site-packages\aiogram\dispatcher\middlewares\error.py", line 25, in __call__
    return await handler(event, data)
  File "C:\Users\alex\projects\mpit\venv\lib\site-packages\aiogram\dispatcher\middlewares\user_context.py", line 27, in __call__
    return await handler(event, data)
  File "C:\Users\alex\projects\mpit\venv\lib\site-packages\aiogram\fsm\middleware.py", line 41, in __call__
    return await handler(event, data)
  File "C:\Users\alex\projects\mpit\venv\lib\site-packages\aiogram\dispatcher\event\telegram.py", line 120, in trigger
    return await wrapped_inner(event, kwargs)
  File "C:\Users\alex\projects\mpit\venv\lib\site-packages\aiogram\dispatcher\event\handler.py", line 42, in call
    return await wrapped()
  File "C:\Users\alex\projects\mpit\venv\lib\site-packages\aiogram\dispatcher\dispatcher.py", line 275, in _listen_update
    return await self.propagate_event(update_type=update_type, event=event, **kwargs)
  File "C:\Users\alex\projects\mpit\venv\lib\site-packages\aiogram\dispatcher\router.py", line 116, in propagate_event
    return await observer.wrap_outer_middleware(_wrapped, event=event, data=kwargs)
  File "C:\Users\alex\projects\mpit\venv\lib\site-packages\aiogram\dispatcher\router.py", line 111, in _wrapped
    return await self._propagate_event(
  File "C:\Users\alex\projects\mpit\venv\lib\site-packages\aiogram\dispatcher\router.py", line 136, in _propagate_event
    response = await observer.trigger(event, **kwargs)
  File "C:\Users\alex\projects\mpit\venv\lib\site-packages\aiogram\dispatcher\event\telegram.py", line 120, in trigger
    return await wrapped_inner(event, kwargs)
  File "C:\Users\alex\projects\mpit\venv\lib\site-packages\aiogram\dispatcher\event\handler.py", line 42, in call
    return await wrapped()
  File "C:\Users\alex\projects\mpit\main.py", line 25, in start
    bot.answer("da")
AttributeError: 'Bot' object has no attribute 'answer'
2023-10-25 18:56:32,527 INFO Update id=430002189 is not handled. Duration 0 ms by bot id=6414216172
2023-10-25 18:56:32,527 ERROR Cause exception while process update id=430002189 by bot id=6414216172
AttributeError: 'Bot' object has no attribute 'answer'
Traceback (most recent call last):
  File "C:\Users\alex\projects\mpit\venv\lib\site-packages\aiogram\dispatcher\dispatcher.py", line 308, in _process_update
    response = await self.feed_update(bot, update, **kwargs)
  File "C:\Users\alex\projects\mpit\venv\lib\site-packages\aiogram\dispatcher\dispatcher.py", line 157, in feed_update
    response = await self.update.wrap_outer_middleware(
  File "C:\Users\alex\projects\mpit\venv\lib\site-packages\aiogram\dispatcher\middlewares\error.py", line 25, in __call__
    return await handler(event, data)
  File "C:\Users\alex\projects\mpit\venv\lib\site-packages\aiogram\dispatcher\middlewares\user_context.py", line 27, in __call__
    return await handler(event, data)
  File "C:\Users\alex\projects\mpit\venv\lib\site-packages\aiogram\fsm\middleware.py", line 41, in __call__
    return await handler(event, data)
  File "C:\Users\alex\projects\mpit\venv\lib\site-packages\aiogram\dispatcher\event\telegram.py", line 120, in trigger
    return await wrapped_inner(event, kwargs)
  File "C:\Users\alex\projects\mpit\venv\lib\site-packages\aiogram\dispatcher\event\handler.py", line 42, in call
    return await wrapped()
  File "C:\Users\alex\projects\mpit\venv\lib\site-packages\aiogram\dispatcher\dispatcher.py", line 275, in _listen_update
    return await self.propagate_event(update_type=update_type, event=event, **kwargs)
  File "C:\Users\alex\projects\mpit\venv\lib\site-packages\aiogram\dispatcher\router.py", line 116, in propagate_event
    return await observer.wrap_outer_middleware(_wrapped, event=event, data=kwargs)
  File "C:\Users\alex\projects\mpit\venv\lib\site-packages\aiogram\dispatcher\router.py", line 111, in _wrapped
    return await self._propagate_event(
  File "C:\Users\alex\projects\mpit\venv\lib\site-packages\aiogram\dispatcher\router.py", line 136, in _propagate_event
    response = await observer.trigger(event, **kwargs)
  File "C:\Users\alex\projects\mpit\venv\lib\site-packages\aiogram\dispatcher\event\telegram.py", line 120, in trigger
    return await wrapped_inner(event, kwargs)
  File "C:\Users\alex\projects\mpit\venv\lib\site-packages\aiogram\dispatcher\event\handler.py", line 42, in call
    return await wrapped()
  File "C:\Users\alex\projects\mpit\main.py", line 25, in start
    bot.answer("da")
AttributeError: 'Bot' object has no attribute 'answer'
2023-10-25 18:56:34,063 INFO Update id=430002190 is not handled. Duration 0 ms by bot id=6414216172
2023-10-25 18:56:34,063 ERROR Cause exception while process update id=430002190 by bot id=6414216172
AttributeError: 'Bot' object has no attribute 'answer'
Traceback (most recent call last):
  File "C:\Users\alex\projects\mpit\venv\lib\site-packages\aiogram\dispatcher\dispatcher.py", line 308, in _process_update
    response = await self.feed_update(bot, update, **kwargs)
  File "C:\Users\alex\projects\mpit\venv\lib\site-packages\aiogram\dispatcher\dispatcher.py", line 157, in feed_update
    response = await self.update.wrap_outer_middleware(
  File "C:\Users\alex\projects\mpit\venv\lib\site-packages\aiogram\dispatcher\middlewares\error.py", line 25, in __call__
    return await handler(event, data)
  File "C:\Users\alex\projects\mpit\venv\lib\site-packages\aiogram\dispatcher\middlewares\user_context.py", line 27, in __call__
    return await handler(event, data)
  File "C:\Users\alex\projects\mpit\venv\lib\site-packages\aiogram\fsm\middleware.py", line 41, in __call__
    return await handler(event, data)
  File "C:\Users\alex\projects\mpit\venv\lib\site-packages\aiogram\dispatcher\event\telegram.py", line 120, in trigger
    return await wrapped_inner(event, kwargs)
  File "C:\Users\alex\projects\mpit\venv\lib\site-packages\aiogram\dispatcher\event\handler.py", line 42, in call
    return await wrapped()
  File "C:\Users\alex\projects\mpit\venv\lib\site-packages\aiogram\dispatcher\dispatcher.py", line 275, in _listen_update
    return await self.propagate_event(update_type=update_type, event=event, **kwargs)
  File "C:\Users\alex\projects\mpit\venv\lib\site-packages\aiogram\dispatcher\router.py", line 116, in propagate_event
    return await observer.wrap_outer_middleware(_wrapped, event=event, data=kwargs)
  File "C:\Users\alex\projects\mpit\venv\lib\site-packages\aiogram\dispatcher\router.py", line 111, in _wrapped
    return await self._propagate_event(
  File "C:\Users\alex\projects\mpit\venv\lib\site-packages\aiogram\dispatcher\router.py", line 136, in _propagate_event
    response = await observer.trigger(event, **kwargs)
  File "C:\Users\alex\projects\mpit\venv\lib\site-packages\aiogram\dispatcher\event\telegram.py", line 120, in trigger
    return await wrapped_inner(event, kwargs)
  File "C:\Users\alex\projects\mpit\venv\lib\site-packages\aiogram\dispatcher\event\handler.py", line 42, in call
    return await wrapped()
  File "C:\Users\alex\projects\mpit\main.py", line 25, in start
    bot.answer("da")
AttributeError: 'Bot' object has no attribute 'answer'
2023-10-25 18:57:48,354 INFO Update id=430002191 is not handled. Duration 0 ms by bot id=6414216172
2023-10-25 18:57:48,354 ERROR Cause exception while process update id=430002191 by bot id=6414216172
AttributeError: 'Bot' object has no attribute 'answer'
Traceback (most recent call last):
  File "C:\Users\alex\projects\mpit\venv\lib\site-packages\aiogram\dispatcher\dispatcher.py", line 308, in _process_update
    response = await self.feed_update(bot, update, **kwargs)
  File "C:\Users\alex\projects\mpit\venv\lib\site-packages\aiogram\dispatcher\dispatcher.py", line 157, in feed_update
    response = await self.update.wrap_outer_middleware(
  File "C:\Users\alex\projects\mpit\venv\lib\site-packages\aiogram\dispatcher\middlewares\error.py", line 25, in __call__
    return await handler(event, data)
  File "C:\Users\alex\projects\mpit\venv\lib\site-packages\aiogram\dispatcher\middlewares\user_context.py", line 27, in __call__
    return await handler(event, data)
  File "C:\Users\alex\projects\mpit\venv\lib\site-packages\aiogram\fsm\middleware.py", line 41, in __call__
    return await handler(event, data)
  File "C:\Users\alex\projects\mpit\venv\lib\site-packages\aiogram\dispatcher\event\telegram.py", line 120, in trigger
    return await wrapped_inner(event, kwargs)
  File "C:\Users\alex\projects\mpit\venv\lib\site-packages\aiogram\dispatcher\event\handler.py", line 42, in call
    return await wrapped()
  File "C:\Users\alex\projects\mpit\venv\lib\site-packages\aiogram\dispatcher\dispatcher.py", line 275, in _listen_update
    return await self.propagate_event(update_type=update_type, event=event, **kwargs)
  File "C:\Users\alex\projects\mpit\venv\lib\site-packages\aiogram\dispatcher\router.py", line 116, in propagate_event
    return await observer.wrap_outer_middleware(_wrapped, event=event, data=kwargs)
  File "C:\Users\alex\projects\mpit\venv\lib\site-packages\aiogram\dispatcher\router.py", line 111, in _wrapped
    return await self._propagate_event(
  File "C:\Users\alex\projects\mpit\venv\lib\site-packages\aiogram\dispatcher\router.py", line 136, in _propagate_event
    response = await observer.trigger(event, **kwargs)
  File "C:\Users\alex\projects\mpit\venv\lib\site-packages\aiogram\dispatcher\event\telegram.py", line 120, in trigger
    return await wrapped_inner(event, kwargs)
  File "C:\Users\alex\projects\mpit\venv\lib\site-packages\aiogram\dispatcher\event\handler.py", line 42, in call
    return await wrapped()
  File "C:\Users\alex\projects\mpit\main.py", line 25, in start
    bot.answer("da")
AttributeError: 'Bot' object has no attribute 'answer'
2023-10-25 18:57:52,068 INFO Update id=430002192 is not handled. Duration 0 ms by bot id=6414216172
2023-10-25 18:57:52,068 ERROR Cause exception while process update id=430002192 by bot id=6414216172
AttributeError: 'Bot' object has no attribute 'answer'
Traceback (most recent call last):
  File "C:\Users\alex\projects\mpit\venv\lib\site-packages\aiogram\dispatcher\dispatcher.py", line 308, in _process_update
    response = await self.feed_update(bot, update, **kwargs)
  File "C:\Users\alex\projects\mpit\venv\lib\site-packages\aiogram\dispatcher\dispatcher.py", line 157, in feed_update
    response = await self.update.wrap_outer_middleware(
  File "C:\Users\alex\projects\mpit\venv\lib\site-packages\aiogram\dispatcher\middlewares\error.py", line 25, in __call__
    return await handler(event, data)
  File "C:\Users\alex\projects\mpit\venv\lib\site-packages\aiogram\dispatcher\middlewares\user_context.py", line 27, in __call__
    return await handler(event, data)
  File "C:\Users\alex\projects\mpit\venv\lib\site-packages\aiogram\fsm\middleware.py", line 41, in __call__
    return await handler(event, data)
  File "C:\Users\alex\projects\mpit\venv\lib\site-packages\aiogram\dispatcher\event\telegram.py", line 120, in trigger
    return await wrapped_inner(event, kwargs)
  File "C:\Users\alex\projects\mpit\venv\lib\site-packages\aiogram\dispatcher\event\handler.py", line 42, in call
    return await wrapped()
  File "C:\Users\alex\projects\mpit\venv\lib\site-packages\aiogram\dispatcher\dispatcher.py", line 275, in _listen_update
    return await self.propagate_event(update_type=update_type, event=event, **kwargs)
  File "C:\Users\alex\projects\mpit\venv\lib\site-packages\aiogram\dispatcher\router.py", line 116, in propagate_event
    return await observer.wrap_outer_middleware(_wrapped, event=event, data=kwargs)
  File "C:\Users\alex\projects\mpit\venv\lib\site-packages\aiogram\dispatcher\router.py", line 111, in _wrapped
    return await self._propagate_event(
  File "C:\Users\alex\projects\mpit\venv\lib\site-packages\aiogram\dispatcher\router.py", line 136, in _propagate_event
    response = await observer.trigger(event, **kwargs)
  File "C:\Users\alex\projects\mpit\venv\lib\site-packages\aiogram\dispatcher\event\telegram.py", line 120, in trigger
    return await wrapped_inner(event, kwargs)
  File "C:\Users\alex\projects\mpit\venv\lib\site-packages\aiogram\dispatcher\event\handler.py", line 42, in call
    return await wrapped()
  File "C:\Users\alex\projects\mpit\main.py", line 25, in start
    bot.answer("da")
AttributeError: 'Bot' object has no attribute 'answer'
2023-10-25 18:57:53,035 INFO Polling stopped
2023-10-25 18:57:53,035 INFO Polling stopped for bot @kurshkosabot id=6414216172 - 'Пресс-служба: часто задаваемые вопросы'
